<sdf version='1.7'>
  <model name='panda'>
    <joint name='world_base' type='fixed'>
      <pose relative_to='__model__'>0 0 0 0 -0 0</pose>
      <parent>world</parent>
      <child>base</child>
    </joint>
    <link name='base'>
      <pose relative_to='world_base'>0 0 0 0 -0 0</pose>
      <inertial>
        <pose>0 0 0.0001 0 -0 0</pose>
        <mass>10.001</mass>
        <inertia>
          <ixx>0.0020009</ixx>
          <ixy>0</ixy>
          <ixz>0</ixz>
          <iyy>0.0020009</iyy>
          <iyz>0</iyz>
          <izz>0.001001</izz>
        </inertia>
      </inertial>
      <collision name='base_collision'>
        <pose>0 0 0.5 0 -0 0</pose>
        <geometry>
          <box>
            <size>0.5 0.5 1</size>
          </box>
        </geometry>
      </collision>
      <collision name='base_fixed_joint_lump__panda_link0_collision_1'>
        <pose>0 0 1 0 -0 0</pose>
        <geometry>
          <mesh>
            <scale>1 1 1</scale>
            <uri>file:///home/atte/advanced-robotics/exercise_4/edu-franka_vs_ws/install/franka_description/share/franka_description/meshes/collision/link0.stl</uri>
          </mesh>
        </geometry>
      </collision>
      <visual name='base_visual'>
        <pose>0 0 0.5 0 -0 0</pose>
        <geometry>
          <box>
            <size>0.5 0.5 1</size>
          </box>
        </geometry>
      </visual>
      <visual name='base_fixed_joint_lump__panda_link0_visual_1'>
        <pose>0 0 1 0 -0 0</pose>
        <geometry>
          <mesh>
            <scale>1 1 1</scale>
            <uri>file:///home/atte/advanced-robotics/exercise_4/edu-franka_vs_ws/install/franka_description/share/franka_description/meshes/visual/link0.dae</uri>
          </mesh>
        </geometry>
      </visual>
    </link>
    <joint name='panda_joint1' type='revolute'>
      <pose relative_to='base'>0 0 1.333 0 -0 0</pose>
      <parent>base</parent>
      <child>panda_link1</child>
      <axis>
        <xyz>0 0 1</xyz>
        <limit>
          <lower>-2.8973</lower>
          <upper>2.8973</upper>
          <effort>87</effort>
          <velocity>2.175</velocity>
        </limit>
        <dynamics>
          <damping>0.003</damping>
          <friction>0</friction>
          <spring_reference>0</spring_reference>
          <spring_stiffness>0</spring_stiffness>
        </dynamics>
      </axis>
    </joint>
    <link name='panda_link1'>
      <pose relative_to='panda_joint1'>0 0 0 0 -0 0</pose>
      <inertial>
        <pose>0 -0.018125 -0.038604 0 -0 0</pose>
        <mass>2.92747</mass>
        <inertia>
          <ixx>0.0239273</ixx>
          <ixy>1.33179e-05</ixy>
          <ixz>-0.000114048</ixz>
          <iyy>0.0224822</iyy>
          <iyz>-0.00199503</iyz>
          <izz>0.0063501</izz>
        </inertia>
      </inertial>
      <collision name='panda_link1_collision'>
        <pose>0 0 0 0 -0 0</pose>
        <geometry>
          <mesh>
            <scale>1 1 1</scale>
            <uri>file:///home/atte/advanced-robotics/exercise_4/edu-franka_vs_ws/install/franka_description/share/franka_description/meshes/collision/link1.stl</uri>
          </mesh>
        </geometry>
      </collision>
      <visual name='panda_link1_visual'>
        <pose>0 0 0 0 -0 0</pose>
        <geometry>
          <mesh>
            <scale>1 1 1</scale>
            <uri>file:///home/atte/advanced-robotics/exercise_4/edu-franka_vs_ws/install/franka_description/share/franka_description/meshes/visual/link1.dae</uri>
          </mesh>
        </geometry>
      </visual>
    </link>
    <joint name='panda_joint2' type='revolute'>
      <pose relative_to='panda_link1'>0 0 0 -1.5708 0 0</pose>
      <parent>panda_link1</parent>
      <child>panda_link2</child>
      <axis>
        <xyz>0 0 1</xyz>
        <limit>
          <lower>-1.7628</lower>
          <upper>1.7628</upper>
          <effort>87</effort>
          <velocity>2.175</velocity>
        </limit>
        <dynamics>
          <damping>0.003</damping>
          <friction>0</friction>
          <spring_reference>0</spring_reference>
          <spring_stiffness>0</spring_stiffness>
        </dynamics>
      </axis>
    </joint>
    <link name='panda_link2'>
      <pose relative_to='panda_joint2'>0 0 0 0 -0 0</pose>
      <inertial>
        <pose>0.003183 -0.074322 0.008815 0 -0 0</pose>
        <mass>2.93554</mass>
        <inertia>
          <ixx>0.0419389</ixx>
          <ixy>0.000202573</ixy>
          <ixz>0.00407778</ixz>
          <iyy>0.0251451</iyy>
          <iyz>-0.00422522</iyz>
          <izz>0.0617021</izz>
        </inertia>
      </inertial>
      <collision name='panda_link2_collision'>
        <pose>0 0 0 0 -0 0</pose>
        <geometry>
          <mesh>
            <scale>1 1 1</scale>
            <uri>file:///home/atte/advanced-robotics/exercise_4/edu-franka_vs_ws/install/franka_description/share/franka_description/meshes/collision/link2.stl</uri>
          </mesh>
        </geometry>
      </collision>
      <visual name='panda_link2_visual'>
        <pose>0 0 0 0 -0 0</pose>
        <geometry>
          <mesh>
            <scale>1 1 1</scale>
            <uri>file:///home/atte/advanced-robotics/exercise_4/edu-franka_vs_ws/install/franka_description/share/franka_description/meshes/visual/link2.dae</uri>
          </mesh>
        </geometry>
      </visual>
    </link>
    <joint name='panda_joint3' type='revolute'>
      <pose relative_to='panda_link2'>0 -0.316 0 1.5708 -0 0</pose>
      <parent>panda_link2</parent>
      <child>panda_link3</child>
      <axis>
        <xyz>0 0 1</xyz>
        <limit>
          <lower>-2.8973</lower>
          <upper>2.8973</upper>
          <effort>87</effort>
          <velocity>2.175</velocity>
        </limit>
        <dynamics>
          <damping>0.003</damping>
          <friction>0</friction>
          <spring_reference>0</spring_reference>
          <spring_stiffness>0</spring_stiffness>
        </dynamics>
      </axis>
    </joint>
    <link name='panda_link3'>
      <pose relative_to='panda_joint3'>0 0 0 0 -0 0</pose>
      <inertial>
        <pose>0.040702 -0.00482 -0.028973 0 -0 0</pose>
        <mass>2.2449</mass>
        <inertia>
          <ixx>0.0241014</ixx>
          <ixy>0.00240469</ixy>
          <ixz>-0.00285627</ixz>
          <iyy>0.0197405</iyy>
          <iyz>-0.00210421</iyz>
          <izz>0.0190445</izz>
        </inertia>
      </inertial>
      <collision name='panda_link3_collision'>
        <pose>0 0 0 0 -0 0</pose>
        <geometry>
          <mesh>
            <scale>1 1 1</scale>
            <uri>file:///home/atte/advanced-robotics/exercise_4/edu-franka_vs_ws/install/franka_description/share/franka_description/meshes/collision/link3.stl</uri>
          </mesh>
        </geometry>
      </collision>
      <visual name='panda_link3_visual'>
        <pose>0 0 0 0 -0 0</pose>
        <geometry>
          <mesh>
            <scale>1 1 1</scale>
            <uri>file:///home/atte/advanced-robotics/exercise_4/edu-franka_vs_ws/install/franka_description/share/franka_description/meshes/visual/link3.dae</uri>
          </mesh>
        </geometry>
      </visual>
    </link>
    <joint name='panda_joint4' type='revolute'>
      <pose relative_to='panda_link3'>0.0825 0 0 1.5708 -0 0</pose>
      <parent>panda_link3</parent>
      <child>panda_link4</child>
      <axis>
        <xyz>0 0 1</xyz>
        <limit>
          <lower>-3.0718</lower>
          <upper>-0.0698</upper>
          <effort>87</effort>
          <velocity>2.175</velocity>
        </limit>
        <dynamics>
          <damping>0.003</damping>
          <friction>0</friction>
          <spring_reference>0</spring_reference>
          <spring_stiffness>0</spring_stiffness>
        </dynamics>
      </axis>
    </joint>
    <link name='panda_link4'>
      <pose relative_to='panda_joint4'>0 0 0 0 -0 0</pose>
      <inertial>
        <pose>-0.04591 0.063049 -0.008519 0 -0 0</pose>
        <mass>2.6156</mass>
        <inertia>
          <ixx>0.03453</ixx>
          <ixy>0.0132255</ixy>
          <ixz>0.0101514</ixz>
          <iyy>0.0288816</iyy>
          <iyz>-0.000976283</iyz>
          <izz>0.0412547</izz>
        </inertia>
      </inertial>
      <collision name='panda_link4_collision'>
        <pose>0 0 0 0 -0 0</pose>
        <geometry>
          <mesh>
            <scale>1 1 1</scale>
            <uri>file:///home/atte/advanced-robotics/exercise_4/edu-franka_vs_ws/install/franka_description/share/franka_description/meshes/collision/link4.stl</uri>
          </mesh>
        </geometry>
      </collision>
      <visual name='panda_link4_visual'>
        <pose>0 0 0 0 -0 0</pose>
        <geometry>
          <mesh>
            <scale>1 1 1</scale>
            <uri>file:///home/atte/advanced-robotics/exercise_4/edu-franka_vs_ws/install/franka_description/share/franka_description/meshes/visual/link4.dae</uri>
          </mesh>
        </geometry>
      </visual>
    </link>
    <joint name='panda_joint5' type='revolute'>
      <pose relative_to='panda_link4'>-0.0825 0.384 0 -1.5708 0 0</pose>
      <parent>panda_link4</parent>
      <child>panda_link5</child>
      <axis>
        <xyz>0 0 1</xyz>
        <limit>
          <lower>-2.8973</lower>
          <upper>2.8973</upper>
          <effort>12</effort>
          <velocity>2.61</velocity>
        </limit>
        <dynamics>
          <damping>0.003</damping>
          <friction>0</friction>
          <spring_reference>0</spring_reference>
          <spring_stiffness>0</spring_stiffness>
        </dynamics>
      </axis>
    </joint>
    <link name='panda_link5'>
      <pose relative_to='panda_joint5'>0 0 0 0 -0 0</pose>
      <inertial>
        <pose>-0.001604 0.029254 -0.097297 0 -0 0</pose>
        <mass>2.32712</mass>
        <inertia>
          <ixx>0.0516103</ixx>
          <ixy>-0.00571517</ixy>
          <ixz>-0.00356732</ixz>
          <iyy>0.0478773</iyy>
          <iyz>0.010674</iyz>
          <izz>0.0164236</izz>
        </inertia>
      </inertial>
      <collision name='panda_link5_collision'>
        <pose>0 0 0 0 -0 0</pose>
        <geometry>
          <mesh>
            <scale>1 1 1</scale>
            <uri>file:///home/atte/advanced-robotics/exercise_4/edu-franka_vs_ws/install/franka_description/share/franka_description/meshes/collision/link5.stl</uri>
          </mesh>
        </geometry>
      </collision>
      <visual name='panda_link5_visual'>
        <pose>0 0 0 0 -0 0</pose>
        <geometry>
          <mesh>
            <scale>1 1 1</scale>
            <uri>file:///home/atte/advanced-robotics/exercise_4/edu-franka_vs_ws/install/franka_description/share/franka_description/meshes/visual/link5.dae</uri>
          </mesh>
        </geometry>
      </visual>
    </link>
    <joint name='panda_joint6' type='revolute'>
      <pose relative_to='panda_link5'>0 0 0 1.5708 -0 0</pose>
      <parent>panda_link5</parent>
      <child>panda_link6</child>
      <axis>
        <xyz>0 0 1</xyz>
        <limit>
          <lower>-0.0175</lower>
          <upper>3.7525</upper>
          <effort>12</effort>
          <velocity>2.61</velocity>
        </limit>
        <dynamics>
          <damping>0.003</damping>
          <friction>0</friction>
          <spring_reference>0</spring_reference>
          <spring_stiffness>0</spring_stiffness>
        </dynamics>
      </axis>
    </joint>
    <link name='panda_link6'>
      <pose relative_to='panda_joint6'>0 0 0 0 -0 0</pose>
      <inertial>
        <pose>0.059713 -0.041029 -0.010169 0 -0 0</pose>
        <mass>1.81704</mass>
        <inertia>
          <ixx>0.00541233</ixx>
          <ixy>0.00619346</ixy>
          <ixz>0.00142193</ixz>
          <iyy>0.0140583</iyy>
          <iyz>-0.00131408</iyz>
          <izz>0.0160808</izz>
        </inertia>
      </inertial>
      <collision name='panda_link6_collision'>
        <pose>0 0 0 0 -0 0</pose>
        <geometry>
          <mesh>
            <scale>1 1 1</scale>
            <uri>file:///home/atte/advanced-robotics/exercise_4/edu-franka_vs_ws/install/franka_description/share/franka_description/meshes/collision/link6.stl</uri>
          </mesh>
        </geometry>
      </collision>
      <visual name='panda_link6_visual'>
        <pose>0 0 0 0 -0 0</pose>
        <geometry>
          <mesh>
            <scale>1 1 1</scale>
            <uri>file:///home/atte/advanced-robotics/exercise_4/edu-franka_vs_ws/install/franka_description/share/franka_description/meshes/visual/link6.dae</uri>
          </mesh>
        </geometry>
      </visual>
    </link>
    <joint name='panda_joint7' type='revolute'>
      <pose relative_to='panda_link6'>0.088 0 0 1.5708 -0 0</pose>
      <parent>panda_link6</parent>
      <child>panda_link7</child>
      <axis>
        <xyz>0 0 1</xyz>
        <limit>
          <lower>-2.8973</lower>
          <upper>2.8973</upper>
          <effort>12</effort>
          <velocity>2.61</velocity>
        </limit>
        <dynamics>
          <damping>0.003</damping>
          <friction>0</friction>
          <spring_reference>0</spring_reference>
          <spring_stiffness>0</spring_stiffness>
        </dynamics>
      </axis>
    </joint>
    <link name='panda_link7'>
      <pose relative_to='panda_joint7'>0 0 0 0 -0 0</pose>
      <inertial>
        <pose>0.004515 0.008612 -0.015967 0 -0 0</pose>
        <mass>0.628143</mass>
        <inertia>
          <ixx>0.000227143</ixx>
          <ixy>-2.43719e-05</ixy>
          <ixz>4.62009e-05</ixz>
          <iyy>0.000193351</iyy>
          <iyz>8.85014e-05</iyz>
          <izz>6.10266e-05</izz>
        </inertia>
      </inertial>
      <collision name='panda_link7_collision'>
        <pose>0 0 0 0 -0 0</pose>
        <geometry>
          <mesh>
            <scale>1 1 1</scale>
            <uri>file:///home/atte/advanced-robotics/exercise_4/edu-franka_vs_ws/install/franka_description/share/franka_description/meshes/collision/link7.stl</uri>
          </mesh>
        </geometry>
      </collision>
      <collision name='panda_link7_fixed_joint_lump__panda_link8_collision_1'>
        <pose>0.0424 0.0424 0.082 1.5708 1.5708 0</pose>
        <geometry>
          <cylinder>
            <length>0.01</length>
            <radius>0.06</radius>
          </cylinder>
        </geometry>
      </collision>
      <collision name='panda_link7_fixed_joint_lump__panda_link8_collision_2'>
        <pose>0.0424 0.0424 0.087 0 -0 0</pose>
        <geometry>
          <sphere>
            <radius>0.06</radius>
          </sphere>
        </geometry>
      </collision>
      <collision name='panda_link7_fixed_joint_lump__panda_link8_collision_3'>
        <pose>0.0424 0.0424 0.077 0 -0 0</pose>
        <geometry>
          <sphere>
            <radius>0.06</radius>
          </sphere>
        </geometry>
      </collision>
      <visual name='panda_link7_visual'>
        <pose>0 0 0 0 -0 0</pose>
        <geometry>
          <mesh>
            <scale>1 1 1</scale>
            <uri>file:///home/atte/advanced-robotics/exercise_4/edu-franka_vs_ws/install/franka_description/share/franka_description/meshes/visual/link7.dae</uri>
          </mesh>
        </geometry>
      </visual>
    </link>
    <static>0</static>
    <plugin name='ign_ros2_control::IgnitionROS2ControlPlugin' filename='ign_ros2_control-system'>
      <robot_param>robot_description</robot_param>
      <robot_param_node>robot_state_publisher</robot_param_node>
      <parameters>/home/atte/advanced-robotics/exercise_4/edu-franka_vs_ws/install/franka_gazebo/share/franka_gazebo/config/franka_controllers.yaml</parameters>
    </plugin>
  </model>
</sdf>
